<mujoco model="man7">
  <compiler angle="radian" meshdir="../meshes/"/>
  <option timestep="0.001" iterations="50" tolerance="1e-10" solver="Newton" jacobian="dense" cone="pyramidal" />
  <default>
    <geom condim="1" type="mesh" />
    <joint limited="true" damping="0.2" pos="0 0 0" />
    <motor ctrllimited="false" forcelimited="false" />
    <default class="collision">
      <geom condim="3" group="0" rgba="0 0 0 0"/>
    </default>
    <default class="visual">
      <geom group="1" conaffinity="0" contype="0" />
    </default>
  </default>
  <asset>
    <mesh name="PELVIS_col" file="convex/PELVIS_S.STL"/>
    <mesh name="L_HIP_R_col" file="convex/L_HIP_R_S.STL"/>
    <mesh name="L_HIP_P_col" file="convex/L_HIP_P_S.STL"/>
    <mesh name="L_HIP_Y_col" file="convex/L_HIP_Y_S.STL"/>
    <mesh name="L_KNEE_P_col" file="convex/L_KNEE_P_S.STL"/>
    <mesh name="L_ANKLE_R_col" file="convex/L_ANKLE_R_S.STL"/>
    <mesh name="R_HIP_R_col" file="convex/R_HIP_R_S.STL"/>
    <mesh name="R_HIP_P_col" file="convex/R_HIP_P_S.STL"/>
    <mesh name="R_HIP_Y_col" file="convex/R_HIP_Y_S.STL"/>
    <mesh name="R_KNEE_P_col" file="convex/R_KNEE_P_S.STL"/>
    <mesh name="R_ANKLE_R_col" file="convex/R_ANKLE_R_S.STL"/>
    <mesh name="WAIST_Y_col" file="convex/WAIST_Y_S.STL"/>
    <mesh name="WAIST_P_col" file="convex/WAIST_P_S.STL"/>
    <mesh name="L_SHOULDER_R_col" file="convex/L_SHOULDER_R_S.STL"/>
    <mesh name="L_SHOULDER_Y_col" file="convex/L_SHOULDER_Y_S.STL"/>
    <mesh name="L_ELBOW_P_col" file="convex/L_ELBOW_P_S.STL"/>
    <mesh name="R_SHOULDER_R_col" file="convex/R_SHOULDER_R_S.STL"/>
    <mesh name="R_SHOULDER_Y_col" file="convex/R_SHOULDER_Y_S.STL"/>
    <mesh name="R_ELBOW_P_col" file="convex/R_ELBOW_P_S.STL"/>
    
    <mesh name="PELVIS_vis" file="visual/PELVIS_S.STL"/>
    <mesh name="L_HIP_Y_vis" file="visual/L_HIP_Y_S.STL"/>
    <mesh name="L_HIP_R_vis" file="visual/L_HIP_R_S.STL"/>
    <mesh name="L_HIP_P_vis" file="visual/L_HIP_P_S.STL"/>
    <mesh name="L_KNEE_P_vis" file="visual/L_KNEE_P_S.STL"/>
    <mesh name="L_ANKLE_P4_vis" file="visual/L_ANKLE_P4_S.STL"/>
    <mesh name="L_ANKLE_R_vis" file="visual/L_ANKLE_R_S.STL"/>
    <mesh name="L_ANKLE_P_vis" file="visual/L_ANKLE_P_S.STL"/>
    <mesh name="L_ANKLE_P2_vis" file="visual/L_ANKLE_P2_S.STL"/>
    <mesh name="L_KNEE_vis" file="visual/L_KNEE_S.STL"/>
    <mesh name="L_KNEE_P1_vis" file="visual/L_KNEE_P1_S.STL"/>
    <mesh name="R_HIP_Y_vis" file="visual/R_HIP_Y_S.STL"/>
    <mesh name="R_HIP_R_vis" file="visual/R_HIP_R_S.STL"/>
    <mesh name="R_HIP_P_vis" file="visual/R_HIP_P_S.STL"/>
    <mesh name="R_KNEE_P_vis" file="visual/R_KNEE_P_S.STL"/>
    <mesh name="R_ANKLE_P4_vis" file="visual/R_ANKLE_P4_S.STL"/>
    <mesh name="R_ANKLE_R_vis" file="visual/R_ANKLE_R_S.STL"/>
    <mesh name="R_ANKLE_P_vis" file="visual/R_ANKLE_P_S.STL"/>
    <mesh name="R_ANKLE_P2_vis" file="visual/R_ANKLE_P2_S.STL"/>
    <mesh name="R_KNEE_vis" file="visual/R_KNEE_S.STL"/>
    <mesh name="R_KNEE_P1_vis" file="visual/R_KNEE_P1_S.STL"/>
    <mesh name="WAIST_R_vis" file="visual/WAIST_R_S.STL"/>
    <mesh name="WAIST_Y_vis" file="visual/WAIST_Y_S.STL"/>
    <mesh name="WAIST_P_vis" file="visual/WAIST_P_S.STL"/>
    <mesh name="L_SHOULDER_P_vis" file="visual/L_SHOULDER_P_S.STL"/>
    <mesh name="L_SHOULDER_R_vis" file="visual/L_SHOULDER_R_S.STL"/>
    <mesh name="L_SHOULDER_Y_vis" file="visual/L_SHOULDER_Y_S.STL"/>
    <mesh name="L_ELBOW_P_vis" file="visual/L_ELBOW_P_S.STL"/>
    <mesh name="R_SHOULDER_P_vis" file="visual/R_SHOULDER_P_S.STL"/>
    <mesh name="R_SHOULDER_R_vis" file="visual/R_SHOULDER_R_S.STL"/>
    <mesh name="R_SHOULDER_Y_vis" file="visual/R_SHOULDER_Y_S.STL"/>
    <mesh name="R_ELBOW_P_vis" file="visual/R_ELBOW_P_S.STL"/>
  </asset>
  <worldbody>
    <light directional="false" diffuse="0.2 0.2 0.2" specular="0 0 0" pos="0 0 2" dir="0 0 -1" castshadow="false" />
    <light mode="targetbodycom" target="PELVIS_S" directional="false" diffuse=".8 .8 .8" specular="0.3 0.3 0.3" pos="0 0 4.0" dir="0 0 -1" />
    <body name="PELVIS_S" pos="0 0 0.97">
	    <freejoint name="root" /> 
	    <inertial pos="0 0 0" mass="1.11909973757949" diaginertia="0.00795678827767079 0.00179893770432253 0.00868203559910644"/>
	    <geom class="visual" mesh="PELVIS_vis"/>
	    <geom class="collision" mesh="PELVIS_col" />
      <site name="imu" size="0.01" pos="0 0 0" />
	    <body name="R_HIP_Y_S" pos="0.1067 -0.105 0">
	      <inertial pos="-0.0436053 -5.62346e-07 -0.0295219" quat="-2.90363e-05 0.397497 -1.69798e-05 0.917603" mass="0.386014" diaginertia="0.000791103 0.00075007 0.000299291"/>
	      <geom class="visual" mesh="R_HIP_Y_vis"/>
	      <geom class="collision" mesh="R_HIP_Y_col" />
	      <joint name="R_HIP_Y" pos="0 0 0" axis="0 0 -1" range="-0.523 0.523"/>
	    <body name="R_HIP_R_S" pos="-0.074 0 -0.09">
		    <inertial pos="0.0503669 0.0188192 -2.1576e-07" quat="0.561661 0.429569 -0.561671 0.429572" mass="0.419998" diaginertia="0.000908031 0.000811693 0.000520492"/>
		    <geom class="visual" mesh="R_HIP_R_vis"/>
		    <geom class="collision" mesh="R_HIP_R_col" />
		    <joint name="R_HIP_R" pos="0 0 0" axis="1 0 0" range="-0.8 0.3"/>
		    <body name="R_HIP_P_S" pos="0.074 0.0252 0">
		      <inertial pos="0.0119949 -0.0381204 -0.248722" quat="-0.703792 0.0316042 0.0263002 0.709215" mass="1.6821" diaginertia="0.0282669 0.0267636 0.00240226"/>
		      <!--inertial pos="0.0128553 -0.0629669 -0.23674" quat="0.707048 0.00313749 0.00245362 0.707154" mass="1.6821" diaginertia="0.0561655 0.0533714 0.00499458"/-->
		      <geom class="visual" mesh="R_HIP_P_vis"/>
		      <geom class="collision" mesh="R_HIP_P_col" />
		      <joint name="R_HIP_P" pos="0 0 0" axis="0 -1 0" range="-1.1 1.5"/>
		    <body name="R_KNEE_S" pos="0 -0.0178 -0.135">
		      <inertial pos="0.00406406 -0.00135985 0.00711341" quat="0.679749 0.168508 0.194689 0.686763" mass="0.27648" diaginertia="0.000478083 0.000270746 0.00021506"/>
		      <geom class="visual" mesh="R_KNEE_vis"/>
		      <joint name="R_KNEE" pos="0 0 0" axis="0 1 0" range="0 2.09"/>
		    <body name="R_KNEE_P1_S" pos="0.019888 0.0171 0.034706">
		      <inertial pos="0 -0.0101 -0.142601" quat="0.707107 0 0 0.707107" mass="0.327213" diaginertia="0.00294441 0.00292476 2.50159e-05"/>
		      <geom class="visual" mesh="R_KNEE_P1_vis"/>
		      <joint name="R_KNEE_P1" pos="0 0 0" axis="0 1 0" range="-2.09 0.3"/>
		    </body>
		  </body>
		  <body name="R_KNEE_P_S" pos="0 0.0229 -0.42">
		    <inertial pos="-0.0417752 -0.0458876 -0.162141" quat="0.706685 0.0981365 0.0893456 0.69497" mass="1.00041" diaginertia="0.0124692 0.0123981 0.000504554"/>
		    <!--inertial pos="-0.0474188 -0.0459252 -0.182363" quat="0.687212 0.0929442 0.0893413 0.714926" mass="0.9909" diaginertia="0.024881 0.0247638 0.000984403"/-->
		    <geom class="visual" mesh="R_KNEE_P_vis"/>
		    <geom class="collision" mesh="R_KNEE_P_col" />
		    <joint name="R_KNEE_P" pos="0 0 0" axis="0 1 0" range="-0.3 2.09"/>
		    <body name="R_ANKLE_P_S" pos="-0.026847 -0.0796 -0.10151">
		      <inertial pos="-0.00151583 0.00304741 0.000875166" quat="0.345721 0.607817 0.616828 0.361328" mass="0.154316" diaginertia="0.000112889 6.06672e-05 5.44375e-05"/>
		      <geom class="visual" mesh="R_ANKLE_P_vis"/>
		      <joint name="R_ANKLE_P" pos="0 0 0" axis="0 -1 0" range="-0.8 0.8"/>
		      <body name="R_ANKLE_P2_S" pos="-0.021651 -0.0111 0.0125">
		        <inertial pos="-0.0342443 0.00279118 -0.129477" quat="0.698254 0.0707022 0.111541 0.703563" mass="0.250237" diaginertia="0.00170098 0.00169422 1.64471e-05"/>
		        <geom class="visual" mesh="R_ANKLE_P2_vis"/>
		        <joint name="R_ANKLE_P2" pos="0 0 0" axis="0 -1 0" range="-0.8 0.8"/>
		      </body>
		    </body>
		    <body name="R_ANKLE_P4_S" pos="-0.094605 -0.0941 -0.3577">
		      <inertial pos="0.0112895 0.0273077 0.000334311" quat="0.71386 0.699363 -0.0307187 0.0187421" mass="0.26318" diaginertia="0.000268693 0.000234066 0.000196706"/>
		      <geom class="visual" mesh="R_ANKLE_P4_vis"/>
		      <joint name="R_ANKLE_P4" pos="0 0 0" axis="0 -1 0" range="-0.8 0.8"/>
		      <body name="R_ANKLE_R_S" pos="0.02595 0.046 0">
		        <inertial pos="0.00622453 0.00173883 -0.0690599" quat="0.00747637 0.705563 -0.00770526 0.708566" mass="0.523642" diaginertia="0.00204457 0.00185377 0.000260323"/>
		        <geom class="visual" mesh="R_ANKLE_R_vis"/>
		        <geom class="collision" mesh="R_ANKLE_R_col" />
		        <joint name="R_ANKLE_R" pos="0 0 0" axis="1 0 0" range="-0.5 0.5"/>
		        <site name="rf_force" size="0.01" pos="0.0 0.0 0.0" />
		      </body>
		    </body>
		  </body>
		</body>
	</body>
</body>
	    <body name="L_HIP_Y_S" pos="0.1067 0.105 0.0005">
	      <inertial pos="-0.0436053 -5.5822e-07 -0.0300219" quat="-2.90363e-05 0.397497 -1.69798e-05 0.917603" mass="0.386014" diaginertia="0.000791103 0.00075007 0.000299291"/>
	      <geom class="visual" mesh="L_HIP_Y_vis"/>
	      <geom class="collision" mesh="L_HIP_Y_col" />
	      <joint name="L_HIP_Y" pos="0 0 0" axis="0 0 -1" range="-0.523 0.523"/>
	      
	      <body name="L_HIP_R_S" pos="-0.074 0 -0.0905">
		      <inertial pos="0.0499852 -0.0188192 0.000744731" quat="0.429572 0.561671 -0.429569 0.561661" mass="0.419998" diaginertia="0.000908031 0.000811693 0.000520492"/>
		      <geom class="visual" mesh="L_HIP_R_vis"/>
		      <geom class="collision" mesh="L_HIP_R_col" />
		      <joint name="L_HIP_R" pos="0 0 0" axis="1 0 0" range="-0.3 0.8"/>
		      <body name="L_HIP_P_S" pos="0.074 -0.0255 0">
		        <inertial pos="0.0119949 0.0381204 -0.248722" quat="0.703792 0.0316042 -0.0263002 0.709215" mass="1.6821" diaginertia="0.0282669 0.0267636 0.00240226"/>
		        <geom class="visual" mesh="L_HIP_P_vis"/>
		        <geom class="collision" mesh="L_HIP_P_col" />
		        <joint name="L_HIP_P" pos="0 0 0" axis="0 1 0" range="-2 1.1"/>
		  <body name="L_KNEE_S" pos="0 0.0181 -0.135">
		    <inertial pos="0.00282442 0.00262662 0.00490584" quat="0.686589 0.195303 0.168991 0.679628" mass="0.276478" diaginertia="0.000475818 0.000269567 0.000213879"/>
		    <geom class="visual" mesh="L_KNEE_vis"/>
		    <joint name="L_KNEE" pos="0 0 0" axis="0 -1 0" range="-2.09 0"/>

		    <body name="L_KNEE_P1_S" pos="0.019888 -0.0121 0.034706">
		      <inertial pos="0 0.0051 -0.142601" quat="0.707107 0 0 0.707107" mass="0.327213" diaginertia="0.00294441 0.00292476 2.50159e-05"/>
		      <geom class="visual" mesh="L_KNEE_P1_vis"/>
		      <joint name="L_KNEE_P1" pos="0 0 0" axis="0 -1 0" range="-0.3 2.09"/>

		    </body>
		  </body>
		  <body name="L_KNEE_P_S" pos="0 -0.0226 -0.42">
		    <inertial pos="-0.0417752 0.0458876 -0.162141" quat="0.706685 0.0981365 0.0893456 0.69497" mass="1.00041" diaginertia="0.0124692 0.0123981 0.000504554"/>
		    <geom class="visual" mesh="L_KNEE_P_vis"/>
		    <geom class="collision" mesh="L_KNEE_P_col" />
		    <joint name="L_KNEE_P" pos="0 0 0" axis="0 -1 0" range="-2.09 0.3"/>
			<body name="L_ANKLE_P_S" pos="-0.026847 0.0796 -0.10151">
		      <inertial pos="-0.00151583 -0.00304741 0.000875166" quat="0.361328 0.616828 0.607817 0.345721" mass="0.154316" diaginertia="0.000112889 6.06672e-05 5.44375e-05"/>
		      <geom class="visual" mesh="L_ANKLE_P_vis"/>
		      <joint name="L_ANKLE_P" pos="0 0 0" axis="0 1 0" range="-0.8 0.8"/>

		      <body name="L_ANKLE_P2_S" pos="-0.021651 0.0111 0.0125">
		        <inertial pos="-0.0342443 -0.00279118 -0.129477" quat="0.703563 0.111541 0.0707022 0.698254" mass="0.250237" diaginertia="0.00170098 0.00169422 1.64471e-05"/>
		        <geom class="visual" mesh="L_ANKLE_P2_vis"/>
		        <joint name="L_ANKLE_P2" pos="0 0 0" axis="0 1 0" range="-0.8 0.8"/>
		      </body>
		    </body>
		    <body name="L_ANKLE_P4_S" pos="-0.094605 0.0941 -0.3577">
		      <inertial pos="0.0112895 -0.0273077 0.000334311" quat="0.71386 0.699363 -0.0307187 0.0187421" mass="0.26318" diaginertia="0.000268693 0.000234066 0.000196706"/>
		      <!--inertial pos="0.000409428 -0.021047 0.000465872" quat="0.991646 -0.0947259 -0.0763875 0.0427881" mass="0.263181" diaginertia="0.000158826 0.000147028 0.000142074"/-->
		      <geom class="visual" mesh="L_ANKLE_P4_vis"/>
		      <joint name="L_ANKLE_P4" pos="0 0 0" axis="0 1 0" range="-0.8 0.8"/>

		      <body name="L_ANKLE_R_S" pos="0.02595 -0.0495 0">
		        <inertial pos="0.00622453 -0.00173883 -0.0690599" quat="0.00747637 0.705563 -0.00770526 0.708566" mass="0.523642" diaginertia="0.00204457 0.00185377 0.000260323"/>
		        <!--inertial pos="0.00155752 -0.00191342 -0.0695507" quat="-0.00235157 0.705325 0.00277676 0.708874" mass="0.52364" diaginertia="0.00293108 0.0026267 0.000376259"/-->
		        <geom class="visual" mesh="L_ANKLE_R_vis"/>
		        <geom class="collision" mesh="L_ANKLE_R_col" />
		        <joint name="L_ANKLE_R" pos="0 0 0" axis="1 0 0" range="-0.5 0.5"/>
		        <site name="lf_force" size="0.01" pos="0.0 0.0 0.0" />
		      </body>
		    </body>
		  </body>
		</body>
	      </body>
	    </body>
	    <body name="WAIST_R_S" pos="0.0597 0 0.065">
	      <inertial pos="0.0147147 1.71251e-07 0.00581657" quat="8.01499e-08 0.570126 1.96577e-06 0.821557" mass="0.152815" diaginertia="0.000196724 0.00015804 0.000109107"/>
	      <geom class="visual" mesh="WAIST_R_vis"/>
		<body name="WAIST_Y_S" pos="0.047 0 0.0247">
		<inertial pos="7.2187e-08 0.00846305 0.0305767" quat="0.693891 -0.136061 0.136063 0.693895" mass="0.130303" diaginertia="0.000182569 0.000148102 8.83884e-05"/>
		<geom class="visual" mesh="WAIST_Y_vis"/>
		<geom class="collision" mesh="WAIST_Y_col" />
		
		<body name="WAIST_P_S" pos="0 0.037277 0.0623">
		  <inertial pos="-0.0139051 -0.0371406 0.180713" quat="0.999767 0.00601119 0.0205269 -0.00285676" mass="1.75329" diaginertia="0.00536717 0.00487879 0.00250459"/>
		  <geom class="visual" mesh="WAIST_P_vis"/>
		  <geom class="collision" mesh="WAIST_P_col" />
		  
		  <body name="L_SHOULDER_P_S" pos="0 0.057223 0.262">
		    <inertial pos="0.00490599 0.0412219 6.40882e-06" quat="0.698761 0.698553 -0.109013 -0.108961" mass="0.15354" diaginertia="0.000153597 0.000121372 9.66352e-05"/>
		    <geom class="visual" mesh="L_SHOULDER_P_vis"/>
		    
		    <body name="L_SHOULDER_R_S" pos="0.035 0.0765 0">
		      <inertial pos="-0.0340204 0.00793169 -0.0566176" quat="0.976253 0.0680724 0.205154 0.0144096" mass="0.219298" diaginertia="0.000280759 0.000267943 0.000156245"/>
		      <geom class="visual" mesh="L_SHOULDER_R_vis"/>
		      <geom class="collision" mesh="L_SHOULDER_R_col" />
		      
		      <body name="L_SHOULDER_Y_S" pos="-0.035 0.017911 -0.12785" quat="0.997574 0.0695399 0.000222398 -0.00319063">
		        <inertial pos="-1.13184e-07 0.00507723 -0.0748516" quat="0.704185 0.0640224 -0.0640276 0.704219" mass="0.107848" diaginertia="0.000162595 0.000149891 4.13704e-05"/>
		        <geom class="visual" mesh="L_SHOULDER_Y_vis"/>
		        <geom class="collision" mesh="L_SHOULDER_Y_col" />
		        
		        <body name="L_ELBOW_P_S" pos="0 0.0305 -0.1209">
		          <inertial pos="-0.00153311 -0.0049434 -0.158442" quat="0.996417 0.0627344 0.000662223 -0.0567182" mass="0.422099" diaginertia="0.00068057 0.00067096 0.000149989"/>
		          <geom class="visual" mesh="L_ELBOW_P_vis"/>
		          <geom class="collision" mesh="L_ELBOW_P_col" />
		          
		        </body>
		      </body>
		    </body>
		  </body>
		  <body name="R_SHOULDER_P_S" pos="0 -0.13178 0.262">
		    <inertial pos="0.00490599 -0.0412219 -6.40932e-06" quat="0.698761 0.698553 0.109013 0.108961" mass="0.15354" diaginertia="0.000153597 0.000121372 9.66352e-05"/>
		    <geom class="visual" mesh="R_SHOULDER_P_vis"/>
		    
		    <body name="R_SHOULDER_R_S" pos="0.035 -0.0765 0">
		      <inertial pos="-0.0340205 -0.00920489 -0.0564246" quat="0.97543 -0.0790015 0.204998 -0.0164625" mass="0.219297" diaginertia="0.000280762 0.000267944 0.000156246"/>
		      <geom class="visual" mesh="R_SHOULDER_R_vis"/>
		      <geom class="collision" mesh="R_SHOULDER_R_col" />
		      
		      <body name="R_SHOULDER_Y_S" pos="-0.035 -0.020785 -0.12742" quat="0.996726 -0.0807637 0.000311182 0.00384067">
		        <inertial pos="1.11369e-07 -0.00507727 -0.0748516" quat="0.704185 -0.0640225 0.0640277 0.704219" mass="0.107848" diaginertia="0.000162595 0.000149891 4.13704e-05"/>
		        <geom class="visual" mesh="R_SHOULDER_Y_vis"/>
		        <geom class="collision" mesh="R_SHOULDER_Y_col" />
		        
		        <body name="R_ELBOW_P_S" pos="0 -0.0205 -0.1209">
		          <inertial pos="0.000490765 -0.0054461 -0.158438" quat="0.996567 -0.0630247 -0.00592519 0.053348" mass="0.4221" diaginertia="0.000680618 0.000670957 0.000149945"/>
		          <geom class="visual" mesh="R_ELBOW_P_vis"/>
		          <geom class="collision" mesh="R_ELBOW_P_col" />
		          
		        </body>
		      </body>
		    </body>
		  </body>
		</body>
	      </body>
	    </body>
	</body>
  </worldbody>
  <contact>
    <exclude body1="WAIST_P_S" body2="L_SHOULDER_R_S" />
    <exclude body1="L_SHOULDER_R_S" body2="L_SHOULDER_Y_S" />
    <exclude body1="L_SHOULDER_Y_S" body2="L_ELBOW_P_S" />
    <exclude body1="WAIST_P_S" body2="R_SHOULDER_R_S" />
    <exclude body1="R_SHOULDER_R_S" body2="R_SHOULDER_Y_S" />
    <exclude body1="R_SHOULDER_Y_S" body2="R_ELBOW_P_S" />
    
    <exclude body1="WAIST_P_S" body2="WAIST_Y_S" />
    <exclude body1="WAIST_P_S" body2="PELVIS_S" />
    <exclude body1="PELVIS_S" body2="WAIST_Y_S" />
    
    <exclude body1="PELVIS_S" body2="L_HIP_P_S" />
    <exclude body1="L_HIP_P_S" body2="L_HIP_R_S" />
	  <exclude body1="L_HIP_P_S" body2="L_HIP_Y_S" />
    <exclude body1="L_HIP_P_S" body2="L_KNEE_P_S" />
    <exclude body1="L_KNEE_P_S" body2="L_ANKLE_R_S" />
    
    <exclude body1="PELVIS_S" body2="R_HIP_P_S" />
    <exclude body1="R_HIP_P_S" body2="R_HIP_R_S" />
	  <exclude body1="R_HIP_P_S" body2="R_HIP_Y_S" />
    <exclude body1="R_HIP_P_S" body2="R_KNEE_P_S" />
    <exclude body1="R_KNEE_P_S" body2="R_ANKLE_R_S" />
  </contact>

  <equality>
     <connect body1="L_ANKLE_P2_S" body2="L_ANKLE_P4_S" anchor="-0.06776 0.00695 -0.25619"/>
     <connect body1="R_ANKLE_P2_S" body2="R_ANKLE_P4_S" anchor="-0.06776 -0.00695 -0.25619"/>
     <connect body1="L_KNEE_P_S" body2="L_KNEE_P1_S" anchor="0.01989 0.0337 0.03471"/>
     <connect body1="R_KNEE_P_S" body2="R_KNEE_P1_S" anchor="0.01989 -0.0337 0.03471"/>      
  </equality>
  <actuator>
    <!-- right leg -->
    <motor name="R_HIP_Y_motor" joint="R_HIP_Y" gear="101"/>
    <motor name="R_HIP_R_motor" joint="R_HIP_R" gear="101"/>
    <motor name="R_HIP_P_motor" joint="R_HIP_P" gear="51"/>
    <motor name="R_KNEE_motor" joint="R_KNEE" gear="51"/>
    <motor name="R_ANKLE_P_motor" joint="R_ANKLE_P" gear="51"/>
    <motor name="R_ANKLE_R_motor" joint="R_ANKLE_R" gear="51"/>
    <!-- left leg -->
    <motor name="L_HIP_Y_motor" joint="L_HIP_Y" gear="101"/>
    <motor name="L_HIP_R_motor" joint="L_HIP_R" gear="101"/>
    <motor name="L_HIP_P_motor" joint="L_HIP_P" gear="51"/>
    <motor name="L_KNEE_motor" joint="L_KNEE" gear="51"/>
    <motor name="L_ANKLE_P_motor" joint="L_ANKLE_P" gear="51"/>
    <motor name="L_ANKLE_R_motor" joint="L_ANKLE_R" gear="51"/>
  </actuator>

  <sensor>
    <!-- F/T sensors -->
    <!-- right foot -->
    <force name="RightFootForceSensor_fsensor" site="rf_force" />
    <torque name="RightFootForceSensor_tsensor" site="rf_force" />
    <!-- left foot -->
    <force name="LeftFootForceSensor_fsensor" site="lf_force" />
    <torque name="LeftFootForceSensor_tsensor" site="lf_force" />
    <!-- imu -->
    <gyro name="Accelerometer_gyro" site="imu" />
    <accelerometer name="Accelerometer_accelerometer" site="imu" />
  </sensor>

</mujoco>
